Traceback (most recent call last):
  File "C:\Users\sam37279\AppData\Local\anaconda3\Lib\site-packages\jupyter_cache\executors\utils.py", line 58, in single_nb_execution
    executenb(
  File "C:\Users\sam37279\AppData\Local\anaconda3\Lib\site-packages\nbclient\client.py", line 1304, in execute
    return NotebookClient(nb=nb, resources=resources, km=km, **kwargs).execute()
           ^^^^^^^^^^^^^^^^^^^^^^^^^^^^^^^^^^^^^^^^^^^^^^^^^^^^^^^^^^^^^^^^^^^^^
  File "C:\Users\sam37279\AppData\Local\anaconda3\Lib\site-packages\jupyter_core\utils\__init__.py", line 173, in wrapped
    return loop.run_until_complete(inner)
           ^^^^^^^^^^^^^^^^^^^^^^^^^^^^^^
  File "C:\Users\sam37279\AppData\Local\anaconda3\Lib\asyncio\base_events.py", line 653, in run_until_complete
    return future.result()
           ^^^^^^^^^^^^^^^
  File "C:\Users\sam37279\AppData\Local\anaconda3\Lib\site-packages\nbclient\client.py", line 705, in async_execute
    await self.async_execute_cell(
  File "C:\Users\sam37279\AppData\Local\anaconda3\Lib\site-packages\nbclient\client.py", line 1020, in async_execute_cell
    await self._check_raise_for_error(cell, cell_index, exec_reply)
  File "C:\Users\sam37279\AppData\Local\anaconda3\Lib\site-packages\nbclient\client.py", line 914, in _check_raise_for_error
    raise CellExecutionError.from_cell_and_msg(cell, exec_reply_content)
nbclient.exceptions.CellExecutionError: An error occurred while executing the following cell:
------------------
PREFIX dcat: <http://www.w3.org/ns/dcat#>
PREFIX dct: <http://purl.org/dc/terms/>
PREFIX dcatde: <http://dcat-ap.de/def/dcatde/>
PREFIX rdfs: <http://www.w3.org/2000/01/rdf-schema#>
PREFIX pg: <http://dcat-ap.de/def/politicalGeocoding/>

SELECT ?contributorID (COUNT(DISTINCT ?datasetTitle) AS ?uniqueDatasetTitleCount)
WHERE {
  ?datasetURI a dcat:Dataset;
              dct:title ?datasetTitle;
              dcatde:contributorID ?contributorID;
              dct:modified ?modified.
  FILTER((LANG(?datasetTitle) = "" || LANG(?datasetTitle) = "de") && CONTAINS(LCASE(?datasetTitle), "baumkataster"))
  FILTER(CONTAINS(STR(?modified), "2022") || CONTAINS(STR(?modified), "2023") || CONTAINS(STR(?modified), "2024"))
}
GROUP BY ?contributorID
------------------

[1;36m  Cell [1;32mIn[1], line 4[1;36m[0m
[1;33m    PREFIX rdfs: <http://www.w3.org/2000/01/rdf-schema#>[0m
[1;37m                                         ^[0m
[1;31mSyntaxError[0m[1;31m:[0m leading zeros in decimal integer literals are not permitted; use an 0o prefix for octal integers

SyntaxError: leading zeros in decimal integer literals are not permitted; use an 0o prefix for octal integers (<ipython-input-1-a130529de162>, line 4)

