Traceback (most recent call last):
  File "C:\Users\sam37279\AppData\Local\anaconda3\Lib\site-packages\jupyter_cache\executors\utils.py", line 58, in single_nb_execution
    executenb(
  File "C:\Users\sam37279\AppData\Local\anaconda3\Lib\site-packages\nbclient\client.py", line 1304, in execute
    return NotebookClient(nb=nb, resources=resources, km=km, **kwargs).execute()
           ^^^^^^^^^^^^^^^^^^^^^^^^^^^^^^^^^^^^^^^^^^^^^^^^^^^^^^^^^^^^^^^^^^^^^
  File "C:\Users\sam37279\AppData\Local\anaconda3\Lib\site-packages\jupyter_core\utils\__init__.py", line 173, in wrapped
    return loop.run_until_complete(inner)
           ^^^^^^^^^^^^^^^^^^^^^^^^^^^^^^
  File "C:\Users\sam37279\AppData\Local\anaconda3\Lib\asyncio\base_events.py", line 653, in run_until_complete
    return future.result()
           ^^^^^^^^^^^^^^^
  File "C:\Users\sam37279\AppData\Local\anaconda3\Lib\site-packages\nbclient\client.py", line 705, in async_execute
    await self.async_execute_cell(
  File "C:\Users\sam37279\AppData\Local\anaconda3\Lib\site-packages\nbclient\client.py", line 1020, in async_execute_cell
    await self._check_raise_for_error(cell, cell_index, exec_reply)
  File "C:\Users\sam37279\AppData\Local\anaconda3\Lib\site-packages\nbclient\client.py", line 914, in _check_raise_for_error
    raise CellExecutionError.from_cell_and_msg(cell, exec_reply_content)
nbclient.exceptions.CellExecutionError: An error occurred while executing the following cell:
------------------
PREFIX dct: <http://purl.org/dc/terms/>
PREFIX dcatde: <http://dcat-ap.de/def/dcatde/>
PREFIX pg: <https://www.dcat-ap.de/def/politicalGeocoding/>

SELECT ?uri ?title ?contributorid ?stateKey
WHERE {
    ?uri dct:title ?title .
    ?uri dcatde:contributorID ?contributorid .
  OPTIONAL {?uri pg:stateKey ?stateKey} .
}
------------------


<Error>: 

